Workbook

Sheet DASHBOARD
B2: Overall # of Test Cases | C2: =SUM(C6,F6,I6) -> 1276
B4: PROGRESS TRACKER | C4: TOTAL SPRINT 1 | E4: PROGRESS TRACKER | F4: TOTAL SPRINT 2 | H4: PROGRESS TRACKER | I4: TOTAL SPRINT 3
B5: Status | E5: Status | H5: Status
B6: Total # of Test Case | C6: =SUM(C7:C11) -> 588 | E6: Total # of Test Case | F6: =SUM(F7:F11) -> 413 | H6: Total # of Test Case | I6: =SUM(I7:I11) -> 275
B7: Not Started | C7: =COUNTIF('Test Case - Sprint 1'!F:F,"NOT STARTED") -> 0 | E7: Not Started | F7: =COUNTIF('Test Case - Sprint 2'!F:F,"NOT STARTED") -> 25 | H7: Not Started | I7: =COUNTIF('Test Case - Sprint 3'!F:F,"NOT STARTED") -> 19
B8: Passed | C8: =COUNTIF('Test Case - Sprint 1'!F:F,"PASSED") -> 587 | E8: Passed | F8: =COUNTIF('Test Case - Sprint 2'!F:F,"PASSED") -> 388 | H8: Passed | I8: =COUNTIF('Test Case - Sprint 3'!F:F,"PASSED") -> 252
B9: Failed | C9: =COUNTIF('Test Case - Sprint 1'!F:F,"FAILED") -> 1 | E9: Failed | F9: =COUNTIF('Test Case - Sprint 2.0'!F:F,"FAILED") -> 0 | H9: Failed | I9: =COUNTIF('Test Case - Sprint 3'!F:F,"FAILED") -> 4
B10: Re-Test | C10: =COUNTIF('Test Case - Sprint 1'!F:F,"Re-Test") -> 0 | E10: Re-Test | F10: =COUNTIF('Test Case - Sprint 2.0'!F:F,"Re-Test") -> 0 | H10: Re-Test | I10: =COUNTIF('Test Case - Sprint 3'!F:F,"Re-Test") -> 0
B11: Blocked/Skip | C11: =COUNTIF('Test Case - Sprint 1'!F:F,"Blocked/Skip") -> 0 | E11: Blocked/Skip | F11: =COUNTIF('Test Case - Sprint 2'!F:F,"Blocked/Skip") -> 0 | H11: Blocked/Skip | I11: =COUNTIF('Test Case - Sprint 3'!F:F,"Blocked/Skip") -> 0
B13: Company | E13: Company | H13: Super Admin
B15: Sign Up | C15: =COUNTIF('Test Case - Sprint 1'!F5:F11,"Passed")/7 -> 1 | E15: Return Orders | H15: Login
B16: Verify Email | C16: =COUNTIF('Test Case - Sprint 1'!F13:F16,"Passed")/4 -> 1 | E16: Receipt Orders | H16: Dashboard
B17: Onboarding | C17: =COUNTIF('Test Case - Sprint 1'!F18:F42,"Passed")/25 -> 1 | E17: Purchase Orders | H17: Companies
B18: Log In | C18: =COUNTIF('Test Case - Sprint 1'!F44:F53,"Passed")/10 -> 1 | E18: Document Management | H18: Wedding Suppliers
B19: Forgot Password | C19: =COUNTIF('Test Case - Sprint 1'!F55:F61,"Passed")/7 -> 1 | E19: Campaign Management | H19: Media Library
B20: Reset Password | C20: =COUNTIF('Test Case - Sprint 1'!F63:F70,"Passed")/8 -> 1 | E20: Project Management | H20: Plans
B21: Profile Settings | C21: =COUNTIF('Test Case - Sprint 1'!F72:F82,"Passed")/11 -> 1 | E21: Calendar | H21: Plan Requests
B22: Dashboard | C22: =COUNTIF('Test Case - Sprint 1'!F84:F109,"Passed")/26 -> 1 | E22: Cases | H22: Plan Orders
B23: Staff - Users | C23: =COUNTIF('Test Case - Sprint 1'!F111:F132,"Passed")/23 -> 0.95652174 | E23: Meetings | H23: Coupons
B24: Staff - Roles | C24: =COUNTIF('Test Case - Sprint 1'!F134:F147,"Passed")/16 -> 0.875 | E24: Calls | H24: Currencies
B25: Lead Statuses | C25: =COUNTIF('Test Case - Sprint 1'!F149:F163,"Passed")/15 -> 1 | E25: Reports | H25: Referral Program
B26: Lead Sources | C26: =COUNTIF('Test Case - Sprint 1'!F165:F175,"Passed")/11 -> 1 | E26: Shipping Provider Types | H26: Landing Page
B27: Leads | C27: =COUNTIF('Test Case - Sprint 1'!F177:F205,"Passed")/30 -> 0.96666667 | E27: Plans | H27: Custom Pages
B28: Opportunity Stages | E28: Referral Program | H28: Contact Messages
B29: Opportunity Sources | E29: Media Library | H29: Newletters
B30: Opportunities | E30: Notification Templates | H30: Email Templates
B31: Account Type | E31: Settings | H31: Settings
B32: Account Industries
B33: Accounts
B34: Contacts
B35: Product Setup - Taxes
B36: Product Setup - Brands
B37: Product Setup - Categories
B38: Products
B39: Quotes
B40: Sales Orders
B41: Invoices
B42: Delivery Orders

Sheet Sheet4
A4: student
A6: Login | B6: Done | D6: =(E6+E7)/14 -> 0.57142857 | E6: =COUNTIF(B6:B19,"Done") -> 8
A7: Forgot password | B7: Done | E7: =COUNTIF(B6:B19,"Partial") -> 0
A8: Reset Password | B8: Done
A9: dashboard | B9: Status | C9: Real-time reflection of amount | D9: Progress bar of payment | E9: n/n months | F9: amount paid deduction
A10: tuition fees | B10: filtering | C10: search | D10: tables | E10: real time status
A11: other transaction
A12: terms and conditions | B12: Done
A13: finance policy | B13: Done | E13: =(D6+D23)/2 -> 0.42857143
A14: FAQ | B14: Done
A15: contact us
A16: header | B16: Done
A17: notification | B17: notifs
A18: Profile Management | B18: Done
A19: pay now | B19: list of banks | C19: upload payment where?
A21: admin
A23: Login | B23: Done | D23: =(E23+E24)/14 -> 0.28571429 | E23: =COUNTIF(B23:B36,"Done") -> 4
A24: Forgot password | B24: Done | E24: =COUNTIF(B23:B35,"Partial") -> 0
A25: Reset Password | B25: Done
A26: dashboard | B26: cards status | C26: filter | D26: status OR | E26: remove history logs?
A27: student management | B27: import csv | C27: search | D27: filter | E27: data tables
A28: payment management | B28: search | C28: filter | D28: data tables
A29: manage OR request | B29: search | C29: filter | D29: OR history
A30: staff management | B30: search | C30: filter | D30: edit access
A31: content management
A32: report management | B32: filter | C32: report csv | D32: status paid or np
A33: profile settings
A34: history logs | B34: activity | C34: data tables | D34: search | E34: filter
A35: header | B35: Done
A36: notification | B36: notifs
A37: view details | B37: PH | C37: MP | D37: view attachment | E37: status

Sheet Test Data Copy
A1: STUDENT | C1: ADMIN
A3: LOGIN | C3: LOGIN
A4: STUDENT ID | B4: alphanumeric which consist of 10 characters | C4: USERNAME
A5: PASSWORD | B5: Minimum of 8 alphanumeric character | C5: PASSWORD | D5: Minimum of 8 alphanumeric character
B6: Maximum of 50 alphanumeric character | D6: Maximum of 50 alphanumeric character
B7: Must have at least one special character | D7: Must have at least one special character
A8: FORGOT PASSWORD | C8: STAFF MANAGEMENT>ADD NEW STAFF
A9: EMAIL ADDRESS | B9: email add | C9: Profile image | D9: jpeg, png; up to 20mb
C10: FIRST NAME | D10: Maximum of 70 characters
A11: PAY | C11: MIDLE NAME | D11: OPTIONAL
A12: UPLOAD PROOF OF PAYMENT | C12: LAST NAME | D12: Maximum of 70 characters
C13: ACCOUNT
C14: ROLE
A15: PAY>MODE OF PAYMENT> CREDIT CARDS> CARD INFORMATION | C15: EMAIL ADDRESS | D15: Maximum of 70 characters
A16: CARD NUMBER | C16: MOBILE NUMBER | D16: Use the 11-digit (e.g. 09171234567) or 12-digit (e.g. 639181234567) format
A17: CARD NAME | C17: HOME ADDRESS | D17: Up to 70 characters
A18: EXPIRY DATE
A19: CVV | C19: STUDENT MANAGEMENT
C20: PAYMENT TRANSACTION
A21: CONTACT US | C21: STAFF MANAGEMENT
A22: NAME | C22: CONTENT MANAGEMENT
A23: STUDENT ID | C23: REPORTS MANAGEMENT
A24: EMAIL ADDRESS
A25: DEPARTMENT | C25: CHANGE PASSWORD
A26: MESSAGE | C26: Current password | D26: current password
C27: new password | D27: Minimum of 8 alphanumeric character
A28: PROFILE SETTINGS | D28: Maximum of 50 alphanumeric character
A29: Upload a Photo | B29: jpeg, png; up to 20mb | D29: Must have at least one special character
A30: Student ID | B30: alphanumeric which consist of 32 characters | C30: confirm password | D30: Minimum of 8 alphanumeric character
A31: Email address | B31: EMAIL | D31: Maximum of 50 alphanumeric character
A32: First name | B32: Maximum of 70 characters | D32: Must have at least one special character
A33: midle name | B33: OPTIONAL
A34: Last name | B34: Maximum of 70 characters | C34: Edit Student Balance
A35: mobile number | B35: Use the 11-digit (e.g. 09171234567) or 12-digit (e.g. 639181234567) format | C35: Current Balance
A36: birthday | B36: DATE PICKET MM/DD/YYYY | C36: payment status
A37: age | C37: enter reason for editing
A38: gender
A39: home address | C39: Add new FAQ Record
A40: course | B40: Pre input | C40: Question
A41: department | B41: Pre input | C41: Answer
...

Sheet Test Data
A1: COMPANY | B1: 1 | C1: 2 | D1: 3 | E1: 4 | F1: 5 | G1: 6 | H1: 7 | I1: 8 | J1: 9 | K1: 10
A24: SUPER ADMIN

Sheet Test Case - Sprint 1
A2: ITEM NO. | B2: TEST CASE / SCENARIO | C2: TEST STEP | D2: EXPECTED RESULT | E2: ACTUAL RESULT (1st RUN) | F2: STATUS | G2: TEST EVIDENCE (1st Run) | H2: COMMENT / REMARK
A3: Company
A4: Sign Up
A5: 1 | B5: Registration page loads | C5: 1. Navigate to Registration page | D5: Registration form loads successfully | F5: Passed
A6: 2 | B6: Successful registration | C6: 1. Enter valid Email 2. Enter Password 3. Enter Confirm Password 4. Check Agree to Terms and Conditions 5. Click Register | D6: User account is created and verification email is sent | F6: Passed
A7: 3 | B7: Password mismatch validation | C7: 1. Enter Password 2. Enter different Confirm Password 3. Click Register | D7: System displays password mismatch validation message | F7: Passed
A8: 4 | B8: Required fields validation | C8: 1. Leave required fields empty 2. Click Register | D8: System displays required field validation messages | F8: Passed
A9: 5 | B9: Terms and conditions required | C9: 1. Fill all fields 2. Do NOT check Agree to Terms 3. Click Register | D9: System prevents registration and prompts user to agree to terms | F9: Passed
A10: 6 | B10: Duplicate email registration | C10: 1. Register using an already existing email | D10: System prevents duplicate registration and displays error message | F10: Passed
A11: 7 | B11: Register with invalid email format | C11: 1. Enter test@example 2. Enter and Confirm password 3.Sign Up | D11: Validation error shown; registration blocked | E11: Accepts email format with no domain extension (e.g. test@example) | F11: Passed | H11: (PASSED) - 03/19/2026
A12: Verify Email
A13: 1 | B13: Verification email received | C13: 1. Register account 2. Check email inbox | D13: Verification email is received successfully | F13: Passed
A14: 2 | B14: Redirect to onboarding after successful email verification | C14: 1. Register a new account 2. Open verification email 3. Click verification link | D14: Email is verified and user is redirected to the onboarding page | F14: Passed
A15: 3 | B15: Invalid verification link | C15: 1. Click expired or modified verification link | D15: System displays invalid or expired link error | F15: Passed
A16: 4 | B16: Login without verification | C16: 1. Attempt to login before verifying email | D16: System restricts login and redirects to verify email page | F16: Passed
A17: Onboarding
A18: 1 | B18: Onboarding page loads successfully | C18: 1. Complete email verification | D18: Onboarding page loads displaying the Company Name setup step | F18: Passed
A19: 2 | B19: Prevent access to dashboard before onboarding completion | C19: 1. Verify email 2. Attempt to directly access dashboard URL | D19: System redirects user to onboarding until setup is completed | F19: Passed
A20: 3 | B20: Onboarding starts with company setup | C20: 1. Verify email 2. Observe first onboarding step | D20: System displays Enter Company Name as the first onboarding step | F20: Passed
A21: 4 | B21: Onboarding session persistence | C21: 1. Verify email 2. Start onboarding 3. Refresh page | D21: Onboarding progress remains and user stays on the same onboarding step | F21: Passed
A22: 5 | B22: Company name entry | C22: 1. Enter Company Name 2. Click Continue | D22: Company name is saved and onboarding proceeds to next step | F22: Passed
A23: 6 | B23: Empty company name validation | C23: 1. Leave Company Name empty 2. Click Continue | D23: System shows required field validation | F23: Passed
A24: 7 | B24: Default roles displayed | C24: 1. Navigate to Roles step | D24: Predefined roles Admin and Sales Manager are displayed | F24: Passed
A25: 8 | B25: Create custom role | C25: 1. Click Create Role 2. Enter Role Name 3. Select permissions 4. Save | D25: Custom role is created successfully | F25: Passed
A26: 9 | B26: Role permissions selection | C26: 1. Create role 2. Select permissions 3. Save | D26: Selected permissions are saved correctly | F26: Passed
A27: 10 | B27: Skip roles setup | C27: 1. Click Skip for Now | D27: System proceeds to next onboarding step | F27: Passed
A28: 11 | B28: Add team member | C28: 1. Enter Name 2. Enter Email 3. Select Role 4. Click Continue | D28: Team member is added successfully | F28: Passed
A29: 12 | B29: Role dropdown selection | C29: 1. Click Role dropdown | D29: Available roles are displayed for selection | F29: Passed
A30: 13 | B30: Invalid email validation | C30: 1. Enter invalid email format 2. Click Continue | D30: System displays email format validation error | E30: Accepts email format with no domain extension (e.g. test@example) | F30: Passed | H30: (PASSED) - 03/19/2026
A31: 14 | B31: Skip team member setup | C31: 1. Click Skip for Now | D31: System proceeds to dashboard | F31: Passed
A32: 15 | B32: Redirect to dashboard after onboarding | C32: 1. Complete onboarding process | D32: User is redirected to the dashboard successfully | F32: Passed
A33: 16 | B33: Dashboard loads correctly | C33: 1. Verify dashboard after onboarding | D33: Dashboard loads with company account initialized | F33: Passed
A34: 17 | B34: Plan subscription pop-up appears on first login | C34: 1. Login using newly registered company account 2. Navigate to Dashboard | D34: Plan subscription pop-up appears automatically on dashboard | F34: Passed
A35: 18 | B35: Display available plans in pop-up | C35: 1. Observe the plans displayed in the pop-up | D35: Available plans are displayed correctly with pricing and plan details | F35: Passed
A36: 19 | B36: Monthly / Yearly pricing toggle | C36: 1. Switch from Monthly to Yearly 2. Switch back to Monthly | D36: Plan pricing updates correctly based on selected billing cycle | F36: Passed
A37: 20 | B37: Subscribe to a plan from pop-up | C37: 1. Click Subscribe on a selected plan | D37: User proceeds to plan subscription or payment process | F37: Passed
A38: 21 | B38: Cancel / Close pop-up | C38: 1. Click Cancel / Close button | D38: Pop-up closes and dashboard remains accessible | F38: Passed
A39: 22 | B39: “Don’t show this again” checkbox functionality | C39: 1. Check Don’t show this again 2. Click Close 3. Refresh dashboard or login again | D39: Plan subscription pop-up no longer appears on dashboard | F39: Passed
A40: 23 | B40: Pop-up reappears when checkbox not selected | C40: 1. Close pop-up without checking Don’t show this again 2. Refresh dashboard or login again | D40: Pop-up appears again on dashboard | F40: Passed
A41: 24 | B41: Plan details correctness in pop-up | C41: 1. Compare plan name, price, and features shown in pop-up | D41: Plan information matches system plan configuration | F41: Passed
...

Sheet Test Case - Sprint 2
A2: ITEM NO. | B2: TEST CASE / SCENARIO | C2: TEST STEP | D2: EXPECTED RESULT | E2: ACTUAL RESULT (1st RUN) | F2: STATUS | G2: TEST EVIDENCE (1st Run) | H2: COMMENT / REMARK
A3: Company
A4: Return Orders
A5: 1 | B5: Return Orders page loads | C5: 1. Navigate to Return Orders module | D5: Return Orders list loads successfully | F5: Passed
A6: 2 | B6: Create Return Order – valid data (happy path) | C6: 1. Click Add Return Order 2. Enter Name 3. Select Sales Order 4. Enter Return Reason 5. Enter Return Date 6. Add Product 7. Click Save | D6: Return Order created successfully | F6: Passed
A7: 3 | B7: Name required validation | C7: 1. Leave Name empty 2. Click Save | D7: Validation error shown | F7: Passed
A8: 4 | B8: Sales Order required validation | C8: 1. Leave Sales Order empty 2. Click Save | D8: Validation error shown | F8: Passed
A9: 5 | B9: Selecting Sales Order auto-populates related fields | C9: 1. Click Add Return Order 2. Select existing Sales Order with products 3. Verify Account field 4. Verify Product & Services section | D9: Account and Contact match Sales Order; product lines available for selection | F9: Passed
A10: 6 | B10: Quantity validation – zero | C10: 1. Enter Quantity = 0 2. Save | D10: Validation error shown | F10: Passed
A11: 7 | B11: Quantity validation – negative | C11: 1. Enter Quantity = -1 2. Save | D11: Validation error shown | F11: Passed
A12: 8 | B12: Unit Price auto-filled | C12: 1. Select Product | D12: Unit Price auto-populated correctly | F12: Passed
A13: 9 | B13: Discount Type – Percentage | C13: 1. Select Discount Type = Percentage 2. Enter Discount Value | D13: Discount calculated correctly | F13: Passed
A14: 10 | B14: Discount Type – Fixed Amount | C14: 1. Select Discount Type = Fixed Amount 2. Enter Discount Value | D14: Discount calculated correctly | F14: Passed
A15: 11 | B15: Final Total calculation | C15: 1. Enter Quantity 2. Apply Discount | D15: Final Total calculated correctly | F15: Passed
A16: 12 | B16: Multiple product lines | C16: 1. Add multiple products 2. Save | D16: Totals calculated correctly | F16: Passed
... A28: 24 | B28: Pagination (10,25,50,100) | C28: 1. Select pagination options | D28: Messages display according to selected limit | F28: Passed
A29: Receipt Orders
A30: 1 | B30: Receipt Orders page loads | C30: 1. Navigate to Receipt Orders module | D30: Receipt Orders list loads successfully | F30: Passed
A31: 2 | B31: Create Receipt Order – valid data | C31: 1. Click Add Receipt Order 2. Enter Name 3. Enter Receipt Date 4. Select Purchase Order or Return Order 5. Add Product 6. Save | D31: Receipt Order created successfully | F31: Passed
A32: 3 | B32: Name required validation | C32: 1. Leave Name empty 2. Click Save | D32: Validation error shown | F32: Passed
A33: 4 | B33: Receipt Date required validation | C33: 1. Leave Receipt Date empty 2. Click Save | D33: Validation error shown | F33: Passed
A34: 5 | B34: Receipt Date before Expected Date | C34: 1. Enter Expected Date 2. Enter earlier Receipt Date 3. Save | D34: System handles consistently (allowed or validated per rule) | F34: Passed
A35: 6 | B35: Selecting Purchase Order auto-populates related fields | C35: 1. Click Add Receipt Order 2. Select existing Purchase Order 3. Verify Account 4. Verify Product lines | D35: Account and products match selected Purchase Order | F35: Passed
A36: 7 | B36: Selecting Return Order auto-populates related fields | C36: 1. Select existing Return Order 2. Verify Account and Product lines | D36: Account and products match selected Return Order | F36: Passed
A37: 8 | B37: Quantity validation – zero | C37: 1. Enter Quantity = 0 2. Save | D37: Validation error shown | F37: Passed
A38: 9 | B38: Quantity validation – negative | C38: 1. Enter Quantity = -1 2. Save | D38: Validation error shown | F38: Passed
A39: 10 | B39: Unit Price auto-filled | C39: 1. Select Product | D39: Unit Price auto-populated correctly | F39: Passed
A40: 11 | B40: Discount Type – Percentage | C40: 1. Select Percentage 2. Enter Discount Value | D40: Discount calculated correctly | F40: Passed
A41: 12 | B41: Discount Type – Fixed Amount | C41: 1. Select Fixed 2. Enter Discount Value | D41: Discount calculated correctly | F41: Passed
... A51: 22 | B51: Pagination (10,25,50,100) | C51: 1. Select pagination options | D51: Messages display according to selected limit | F51: Passed
A52: Purchase Orders
A53: 1 | B53: Purchase Orders page loads | C53: 1. Navigate to Purchase Orders module | D53: Purchase Orders list loads successfully | F53: Passed
A54: 2 | B54: Create Purchase Order – valid data | C54: 1. Click Add Purchase Order 2. Enter Name 3. Enter Order Date 4. Select Account 5. Add Product 6. Save | D54: Purchase Order created successfully | F54: Passed
A55: 3 | B55: Name required validation | C55: Name required validation | D55: Validation error shown | F55: Passed
A56: 4 | B56: Order Date required validation | C56: 1. Leave Order Date empty 2. Click Save | D56: Validation error shown | F56: Passed
A57: 5 | B57: Expected Delivery Date before Order Date | C57: 1. Enter Order Date 2. Enter earlier Expected Delivery Date 3. Save | D57: 1. Enter Order Date 2. Enter earlier Expected Delivery Date 3. Save | F57: Passed
A58: 6 | B58: Selecting Sales Order auto-populates related fields | C58: 1. Click Add Purchase Order 2. Select Sales Order 3. Verify Account and product data | D58: Account and products, and shipping provider match Sales Order | F58: Passed
A59: 7 | B59: Changing Sales Order resets product data | C59: 1. Select Sales Order A 2. Change to Sales Order B | D59: Product data updates accordingl | F59: Passed
A60: 8 | B60: Product data updates accordingl | C60: 1. Click Add under Product & Services 2. Select Product 3. Enter Quantity | D60: Product line added successfully | F60: Passed
A61: 9 | B61: Quantity validation – zero | C61: Quantity validation – zero | D61: 1. Enter Quantity = 0 2. Save | F61: Passed
...

Sheet Test Case - Sprint 2.0
A2: ITEM NO. | B2: TEST CASE / SCENARIO | C2: TEST STEP | D2: SEVERITY | E2: EXPECTED RESULT | F2: ACTUAL RESULT (1st RUN) | G2: STATUS | H2: TEST EVIDENCE (1st Run) | I2: COMMENT / REMARK
A3: STUDENT
A4: Notification
B5: Notifications | C5: 1. Click Bell icon 2. Click any Notification | E5: • User will be redirected to the notification (Tuition fees, Other transaction) | G5: NOT YET STARTED
A6: Other Transaction
B7: Menu - Dashboard - Overview | C7: 1. Click Dashboard Button | E7: • User will be redirected to Dashboards • User will be able to view the overview that consists of: - Profile Picture - Full name - Student ID - Academic Year - Year Level - Semester - Course - Department • User will be able to view Outstanding balance - Tooltip icon - outstanding balance (Hover Tooltip) - Progress bar & number of months - Amount Paid - Total - Pay button --------------------------------------------------- - Due on - Extended Due on | G7: NOT YET STARTED
B8: Menu - Dashboard - Recent Activity | C8: 1. Click Dashboard Button | E8: • User will be redirected to Dashboards • User will be able to view the Recent Activity that consists of: Latest Transactions - View All link - Details of Latest Transaction Official Receipt - View All link - Details of Latest Transaction - View Receeipt Link - Processing of OR must not be seen in this table | G8: NOT YET STARTED
B9: Menu - Tuition fees | C9: 1. Click Tuition Fees Button | E9: • User can be able to view - Pay outstanding balance - Search - Date Range - Filter by (Payment Status / OR status) Tuition Table - Reference No. - Date of payment - Payment Status - Amount - Official Receipt Status - Pagination | G9: NOT YET STARTED
B10: Support - Terms and Conditions | C10: 1. Click Terms and Conditions Button | E10: • User is able to view Terms and Conditions • User is able to view the Last Revised | G10: NOT YET STARTED
B11: Support - Finance Policy | C11: 1. Click Finance Policy Button | E11: • User is able to view Finance Policy • User is able to view the Last Revised | G11: NOT YET STARTED
B12: Support - FAQs | C12: 1. Click FAQs Button | E12: • User is able to view FAQs | G12: NOT YET STARTED
B13: Support - Contact us | C13: 1. Click Contact us Button | E13: • User is able to view Contact us -Send us an Email - Contact details | G13: NOT YET STARTED
A14: Terms & Conditions
B15: Menu - Dashboard - Overview | C15: 1. Click Dashboard Button | E15: • User will be redirected to Dashboards • User will be able to view the overview that consists of: - Profile Picture - Full name - Student ID - Academic Year - Year Level - Semester - Course - Department • User will be able to view Outstanding balance - Tooltip icon - outstanding balance (Hover Tooltip) - Progress bar & number of months - Amount Paid - Total - Pay button --------------------------------------------------- - Due on - Extended Due on | G15: NOT YET STARTED
B16: Menu - Dashboard - Recent Activity | C16: 1. Click Dashboard Button | E16: • User will be redirected to Dashboards • User will be able to view the Recent Activity that consists of: Latest Transactions - View All link - Details of Latest Transaction Official Receipt - View All link - Details of Latest Transaction - View Receeipt Link - Processing of OR must not be seen in this table | G16: NOT YET STARTED
B17: Menu - Tuition fees | C17: 1. Click Tuition Fees Button | E17: • User can be able to view - Pay outstanding balance - Search - Date Range - Filter by (Payment Status / OR status) Tuition Table - Reference No. - Date of payment - Payment Status - Amount - Official Receipt Status - Pagination | G17: NOT YET STARTED
B18: Menu - Other Transactions | C18: 1. Click Other Transaction Button | E18: • User can be able to view - Pay other fees - Search - Date Range Other Transaction Table - Reference No. - Date of payment - Payment Status - Miscellaneous item - Amount - Payment Channel - Pagination | G18: NOT YET STARTED
B19: Support - Finance Policy | C19: 1. Click Finance Policy Button | E19: • User is able to view Finance Policy • User is able to view the Last Revised | G19: NOT YET STARTED
B20: Support - FAQs | C20: 1. Click FAQs Button | E20: • User is able to view FAQs | G20: NOT YET STARTED
B21: Support - Contact us | C21: 1. Click Contact us Button | E21: • User is able to view Contact us -Send us an Email - Contact details | G21: NOT YET STARTED
B22: Terms and Condition | C22: 1. View Terms & Conditions | E22: • View Terms and Conditions Content | G22: NOT YET STARTED
B23: Terms and Condition - Last Revised | C23: 1. View Terms & Conditions | E23: • Last Revised must be updated when the Terms and Conditions is revised | G23: NOT YET STARTED
A24: Finance Policy
B25: Menu - Dashboard - Overview | C25: 1. Click Dashboard Button | E25: • User will be redirected to Dashboards • User will be able to view the overview that consists of: - Profile Picture - Full name - Student ID - Academic Year - Year Level - Semester - Course - Department • User will be able to view Outstanding balance - Tooltip icon - outstanding balance (Hover Tooltip) - Progress bar & number of months - Amount Paid - Total - Pay button --------------------------------------------------- - Due on - Extended Due on | G25: NOT YET STARTED
B26: Menu - Dashboard - Recent Activity | C26: 1. Click Dashboard Button | E26: • User will be redirected to Dashboards • User will be able to view the Recent Activity that consists of: Latest Transactions - View All link - Details of Latest Transaction Official Receipt - View All link - Details of Latest Transaction - View Receeipt Link - Processing of OR must not be seen in this table | G26: NOT YET STARTED
B27: Menu - Tuition fees | C27: 1. Click Tuition Fees Button | E27: • User can be able to view - Pay outstanding balance - Search - Date Range - Filter by (Payment Status / OR status) Tuition Table - Reference No. - Date of payment - Payment Status - Amount - Official Receipt Status - Pagination | G27: NOT YET STARTED
B28: Menu - Other Transactions | C28: 1. Click Other Transaction Button | E28: • User can be able to view - Pay other fees - Search - Date Range Other Transaction Table - Reference No. - Date of payment - Payment Status - Miscellaneous item - Amount - Payment Channel - Pagination | G28: NOT YET STARTED
B29: Support - Terms and Conditions | C29: 1. Click Terms and Conditions Button | E29: • User is able to view Terms and Conditions • User is able to view the Last Revised | G29: NOT YET STARTED
B30: Support - FAQs | C30: 1. Click FAQs Button | E30: • User is able to view FAQs | G30: NOT YET STARTED
B31: Support - Contact us | C31: 1. Click Contact us Button | E31: • User is able to view Contact us -Send us an Email - Contact details | G31: NOT YET STARTED
B32: Finance Policy | C32: 1. View Terms & Conditions | E32: • View Terms and Conditions Content | G32: NOT YET STARTED
B33: Finance Policy - Last Revised | C33: 1. View Terms & Conditions | E33: • Last Revised must be updated when the Terms and Conditions is revised | G33: NOT YET STARTED
A34: FAQs
B35: Menu - Dashboard - Overview | C35: 1. Click Dashboard Button | E35: • User will be redirected to Dashboards • User will be able to view the overview that consists of: - Profile Picture - Full name - Student ID - Academic Year - Year Level - Semester - Course - Department • User will be able to view Outstanding balance - Tooltip icon - outstanding balance (Hover Tooltip) - Progress bar & number of months - Amount Paid - Total - Pay button --------------------------------------------------- - Due on - Extended Due on | G35: NOT YET STARTED
B36: Menu - Dashboard - Recent Activity | C36: 1. Click Dashboard Button | E36: • User will be redirected to Dashboards • User will be able to view the Recent Activity that consists of: Latest Transactions - View All link - Details of Latest Transaction Official Receipt - View All link - Details of Latest Transaction - View Receeipt Link - Processing of OR must not be seen in this table | G36: NOT YET STARTED
B37: Menu - Tuition fees | C37: 1. Click Tuition Fees Button | E37: • User can be able to view - Pay outstanding balance - Search - Date Range - Filter by (Payment Status / OR status) Tuition Table - Reference No. - Date of payment - Payment Status - Amount - Official Receipt Status - Pagination | G37: NOT YET STARTED
B38: Menu - Other Transactions | C38: 1. Click Other Transaction Button | E38: • User can be able to view - Pay other fees - Search - Date Range Other Transaction Table - Reference No. - Date of payment - Payment Status - Miscellaneous item - Amount - Payment Channel - Pagination | G38: NOT YET STARTED
B39: Support - Terms and Conditions | C39: 1. Click Terms and Conditions Button | E39: • User is able to view Terms and Conditions • User is able to view the Last Revised | G39: NOT YET STARTED
B40: Support - Finance Policy | C40: 1. Click Finance Policy Button | E40: • User is able to view Finance Policy • User is able to view the Last Revised | G40: NOT YET STARTED
B41: Support - Contact us | C41: 1. Click Contact us Button | E41: • User is able to view Contact us -Send us an Email - Contact details | G41: NOT YET STARTED
...

Sheet Test Case - Sprint 3
A2: ITEM NO. | B2: TEST CASE / SCENARIO | C2: TEST STEP | D2: EXPECTED RESULT | E2: ACTUAL RESULT (1st RUN) | F2: STATUS | G2: TEST EVIDENCE (1st Run) | H2: COMMENT / REMARK
A3: Super Admin
A4: Sign In
A5: 1 | B5: Login page loads successfully | C5: 1. Click Login | D5: Login page loads with all required fields/buttons visible | F5: Passed
A6: 2 | B6: Login – valid credentials | C6: 1. Enter valid email 2. Enter valid password 3. Click Login | D6: User logs in successfully and is redirected to Dashboard | F6: Passed
A7: 3 | B7: Login using Enter key | C7: 1. Enter valid email & password 2. Press Enter | D7: Login is triggered and user is redirected | F7: Passed
A8: 4 | B8: Login with invalid email format | C8: 1. Enter test@ 2. Enter password 3. Login | D8: Validation error shown; login blocked | F8: Passed
A9: 5 | B9: Login – non-existing email | C9: 1. Enter email not in system 2. Any password 3. Login | D9: Error shown; user not logged in | F9: Passed
A10: 6 | B10: Login – blank email | C10: 1. Leave email empty 2. Enter password 3. Login | D10: Required validation appears; no login | F10: Passed
A11: 7 | B11: Login – invalid password | C11: 1. Enter valid email 2. Wrong password 3. Login | D11: Error shown; user not logged in | F11: Passed
A12: 8 | B12: Login – blank password | C12: 1. Enter email 2. Leave password empty 3. Login | D12: Required validation appears; no login | F12: Passed
A13: 9 | B13: Login – both fields blank | C13: 1. Leave email & password empty 2. Login | D13: Required validations shown | F13: Passed
A14: 10 | B14: Password masked by default | C14: 1. Type password | D14: Password characters are masked | F14: Passed
A15: Dashboard
A16: 1 | B16: Dashboard page loads | C16: 1. Login as Super Admin 2. Navigate to Dashboard | D16: Dashboard loads successfully with all widgets displayed | F16: Passed
A17: 2 | B17: Total Company widget accuracy | C17: 1. Check Total Company count on Dashboard 2. Compare with Companies module count | D17: Total Company count matches actual number of companies | F17: Passed
A18: 3 | B18: Total Users widget accuracy | C18: 1. View Total Users widget 2. Compare with system users list | D18: Total Users value matches actual users in system | F18: Passed
A19: 4 | B19: Active Subscriptions display | C19: 1. View Active Subscriptions widget | D19: Correct number of active subscriptions displayed | F19: Passed
A20: 5 | B20: Monthly Growth chart display | C20: 1. Observe Monthly Growth chart | D20: Chart loads successfully and reflects system growth data | F20: Passed
A21: 6 | B21: Total Revenue widget accuracy | C21: 1. Check Total Revenue value 2. Compare with payment transactions | D21: Revenue value matches recorded payments | F21: Passed
A22: 7 | B22: Recent Activity feed | C22: 1. View Recent Activity section | D22: Recent system activities are displayed correctly | F22: Passed
A23: 8 | B23: Top Performing Plans display | C23: 1. View Top Performing Plans widget | D23: Plans ranked correctly based on subscriptions | F23: Passed
A24: 9 | B24: Payment Transaction Log display | C24: 1. View Payment Transaction Log section | D24: Recent payment transactions displayed correctly | F24: Passed
A25: 10 | B25: Company Management Explore button | C25: 1. Click Explore under Company Management | D25: System redirects to Companies module | F25: Not Started
A26: 11 | B26: Subscription Management Explore button | C26: 1. Click Explore under Subscription Management | D26: System redirects to Subscription Management module | F26: Not Started
A27: 12 | B27: Revenue Tracking Explore button | C27: 1. Click Explore under Revenue Tracking | D27: System redirects to Revenue Tracking module | F27: Not Started
A28: 13 | B28: System Growth Explore button | C28: 1. Click Explore under System Growth | D28: System redirects to System Growth module | F28: Not Started
A29: Companies
A30: 1 | B30: Companies page loads | C30: 1. Navigate to Companies module | D30: Companies page loads successfully | F30: Passed
A31: 2 | B31: Add company (valid data) | C31: 1. Click Add Company 2. Enter Company Name 3. Enter Email 4. Enable Login toggle 5. Enter Password 6. Save | D31: Company created successfully and appears in list | F31: Passed
A32: 3 | B32: Required field validation (Company Name) | C32: 1. Leave Company Name empty 2. Click Save | D32: System displays validation error | F32: Passed
A33: 4 | B33: Required field validation (Email) | C33: 1. Leave Email empty 2. Click Save | D33: System displays validation error | F33: Passed
A34: 5 | B34: Invalid email format validation | C34: 1. Enter invalid email format 2. Click Save | D34: System shows validation error | E34: Accepts email format with no domain extension (e.g. test@example) | F34: Passed | G34: (PASSED) 03/19/2026
A35: 6 | B35: Login toggle behavior | C35: 1. Enable Login toggle | D35: Password field becomes required | F35: Passed
A36: 7 | B36: Disable login toggle | C36: 1. Disable login toggle | D36: Password field becomes optional or hidden | F36: Passed
A37: 8 | B37: Switch to List View | C37: Click List View option | D37: Companies displayed in list format | F37: Passed
A38: 9 | B38: Switch to Grid View | C38: Click Grid View option | D38: Companies displayed in grid format | E38: UI Overflow on some companies with longer details | F38: Passed | G38: (PASSED) 03/24/2026
A39: 10 | B39: Grid view displays company details | C39: 1. Open Grid View | D39: Company cards display correct details (company name, email, status, etc.) | F39: Passed
A40: 11 | B40: Search company by name | C40: Enter company name in search | D40: Matching companies displayed | F40: Passed
A41: 12 | B41: Search company by email | C41: Enter company email | D41: Correct company displayed | F41: Passed
...
